2024-07-24 16:28:53,378 INFO    Thread-138 (_run_job):9552 [wandb_setup.py:_flush():76] Current SDK version is 0.17.4
2024-07-24 16:28:53,378 INFO    Thread-138 (_run_job):9552 [wandb_setup.py:_flush():76] Configure stats pid to 9552
2024-07-24 16:28:53,378 INFO    Thread-138 (_run_job):9552 [wandb_setup.py:_flush():76] Loading settings from C:\Users\ge84gac\.config\wandb\settings
2024-07-24 16:28:53,378 INFO    Thread-138 (_run_job):9552 [wandb_setup.py:_flush():76] Loading settings from C:\Users\ge84gac\Gate_qbm\tests\wandb\settings
2024-07-24 16:28:53,378 INFO    Thread-138 (_run_job):9552 [wandb_setup.py:_flush():76] Loading settings from environment variables: {'entity': 'shivang_arora', 'project': 'Gate-qbm-anomaly-detection-multiple', 'root_dir': 'C:\\Users\\ge84gac\\Gate_qbm\\tests', 'run_id': 'sbiizh6w', 'sweep_param_path': 'C:\\Users\\ge84gac\\Gate_qbm\\tests\\wandb\\sweep-luy6a2ic\\config-sbiizh6w.yaml', 'sweep_id': 'luy6a2ic'}
2024-07-24 16:28:53,381 INFO    Thread-138 (_run_job):9552 [wandb_setup.py:_flush():76] Applying setup settings: {'_disable_service': False}
2024-07-24 16:28:53,381 INFO    Thread-138 (_run_job):9552 [wandb_setup.py:_flush():76] Inferring run settings from compute environment: {'program': '<python with no main file>'}
2024-07-24 16:28:53,381 INFO    Thread-138 (_run_job):9552 [wandb_setup.py:_flush():76] Applying login settings: {}
2024-07-24 16:28:53,381 INFO    Thread-138 (_run_job):9552 [wandb_init.py:_log_setup():529] Logging user logs to C:\Users\ge84gac\Gate_qbm\tests\wandb\run-20240724_162853-sbiizh6w\logs\debug.log
2024-07-24 16:28:53,381 INFO    Thread-138 (_run_job):9552 [wandb_init.py:_log_setup():530] Logging internal logs to C:\Users\ge84gac\Gate_qbm\tests\wandb\run-20240724_162853-sbiizh6w\logs\debug-internal.log
2024-07-24 16:28:53,381 INFO    Thread-138 (_run_job):9552 [wandb_init.py:_jupyter_setup():475] configuring jupyter hooks <wandb.sdk.wandb_init._WandbInit object at 0x00000275326355D0>
2024-07-24 16:28:53,381 INFO    Thread-138 (_run_job):9552 [wandb_init.py:init():569] calling init triggers
2024-07-24 16:28:53,381 INFO    Thread-138 (_run_job):9552 [wandb_init.py:init():576] wandb.init called with sweep_config: {'batchsize': 68, 'beta_eff': 1.0398944107506296, 'epochs': 17, 'hnodes': 1, 'learning_rate': 0.7405226979387342}
config: {}
2024-07-24 16:28:53,381 INFO    Thread-138 (_run_job):9552 [wandb_init.py:init():619] starting backend
2024-07-24 16:28:53,381 INFO    Thread-138 (_run_job):9552 [wandb_init.py:init():623] setting up manager
2024-07-24 16:28:53,381 INFO    Thread-138 (_run_job):9552 [backend.py:_multiprocessing_setup():105] multiprocessing start_methods=spawn, using: spawn
2024-07-24 16:28:53,381 INFO    Thread-138 (_run_job):9552 [wandb_init.py:init():631] backend started and connected
2024-07-24 16:28:53,410 INFO    Thread-138 (_run_job):9552 [wandb_run.py:_config_callback():1382] config_cb None None {'batchsize': 68, 'beta_eff': 1.0398944107506296, 'epochs': 17, 'hnodes': 1, 'learning_rate': 0.7405226979387342}
2024-07-24 16:28:53,410 INFO    Thread-138 (_run_job):9552 [wandb_run.py:_label_probe_notebook():1334] probe notebook
2024-07-24 16:28:53,410 INFO    Thread-138 (_run_job):9552 [wandb_run.py:_label_probe_notebook():1344] Unable to probe notebook: 'NoneType' object has no attribute 'get'
2024-07-24 16:28:53,410 INFO    Thread-138 (_run_job):9552 [wandb_init.py:init():720] updated telemetry
2024-07-24 16:28:53,559 INFO    Thread-138 (_run_job):9552 [wandb_init.py:init():753] communicating run to backend with 90.0 second timeout
2024-07-24 16:28:54,092 INFO    Thread-138 (_run_job):9552 [wandb_run.py:_on_init():2402] communicating current version
2024-07-24 16:28:54,220 INFO    Thread-138 (_run_job):9552 [wandb_run.py:_on_init():2411] got version response upgrade_message: "wandb version 0.17.5 is available!  To upgrade, please run:\n $ pip install wandb --upgrade"

2024-07-24 16:28:54,220 INFO    Thread-138 (_run_job):9552 [wandb_init.py:init():804] starting run threads in backend
2024-07-24 16:29:02,700 INFO    Thread-138 (_run_job):9552 [wandb_run.py:_console_start():2380] atexit reg
2024-07-24 16:29:02,700 INFO    Thread-138 (_run_job):9552 [wandb_run.py:_redirect():2235] redirect: wrap_raw
2024-07-24 16:29:02,700 INFO    Thread-138 (_run_job):9552 [wandb_run.py:_redirect():2300] Wrapping output streams.
2024-07-24 16:29:02,700 INFO    Thread-138 (_run_job):9552 [wandb_run.py:_redirect():2325] Redirects installed.
2024-07-24 16:29:02,702 INFO    Thread-138 (_run_job):9552 [wandb_init.py:init():847] run started, returning control to user process
2024-07-24 16:29:02,702 INFO    Thread-138 (_run_job):9552 [wandb_run.py:_config_callback():1382] config_cb None None {'restricted': 'false'}
2024-07-24 17:25:29,571 INFO    Thread-10 (_heartbeat):9552 [retry.py:__call__():172] Retry attempt failed:
Traceback (most recent call last):
  File "C:\Users\ge84gac\.conda\envs\qbmqsp\Lib\site-packages\urllib3\connection.py", line 198, in _new_conn
    sock = connection.create_connection(
           ^^^^^^^^^^^^^^^^^^^^^^^^^^^^^
  File "C:\Users\ge84gac\.conda\envs\qbmqsp\Lib\site-packages\urllib3\util\connection.py", line 60, in create_connection
    for res in socket.getaddrinfo(host, port, family, socket.SOCK_STREAM):
               ^^^^^^^^^^^^^^^^^^^^^^^^^^^^^^^^^^^^^^^^^^^^^^^^^^^^^^^^^^
  File "C:\Users\ge84gac\.conda\envs\qbmqsp\Lib\socket.py", line 961, in getaddrinfo
    for res in _socket.getaddrinfo(host, port, family, type, proto, flags):
               ^^^^^^^^^^^^^^^^^^^^^^^^^^^^^^^^^^^^^^^^^^^^^^^^^^^^^^^^^^^
socket.gaierror: [Errno 11001] getaddrinfo failed

The above exception was the direct cause of the following exception:

Traceback (most recent call last):
  File "C:\Users\ge84gac\.conda\envs\qbmqsp\Lib\site-packages\urllib3\connectionpool.py", line 793, in urlopen
    response = self._make_request(
               ^^^^^^^^^^^^^^^^^^^
  File "C:\Users\ge84gac\.conda\envs\qbmqsp\Lib\site-packages\urllib3\connectionpool.py", line 491, in _make_request
    raise new_e
  File "C:\Users\ge84gac\.conda\envs\qbmqsp\Lib\site-packages\urllib3\connectionpool.py", line 467, in _make_request
    self._validate_conn(conn)
  File "C:\Users\ge84gac\.conda\envs\qbmqsp\Lib\site-packages\urllib3\connectionpool.py", line 1099, in _validate_conn
    conn.connect()
  File "C:\Users\ge84gac\.conda\envs\qbmqsp\Lib\site-packages\urllib3\connection.py", line 616, in connect
    self.sock = sock = self._new_conn()
                       ^^^^^^^^^^^^^^^^
  File "C:\Users\ge84gac\.conda\envs\qbmqsp\Lib\site-packages\urllib3\connection.py", line 205, in _new_conn
    raise NameResolutionError(self.host, self, e) from e
urllib3.exceptions.NameResolutionError: <urllib3.connection.HTTPSConnection object at 0x0000027533BCF710>: Failed to resolve 'api.wandb.ai' ([Errno 11001] getaddrinfo failed)

The above exception was the direct cause of the following exception:

Traceback (most recent call last):
  File "C:\Users\ge84gac\.conda\envs\qbmqsp\Lib\site-packages\requests\adapters.py", line 589, in send
    resp = conn.urlopen(
           ^^^^^^^^^^^^^
  File "C:\Users\ge84gac\.conda\envs\qbmqsp\Lib\site-packages\urllib3\connectionpool.py", line 847, in urlopen
    retries = retries.increment(
              ^^^^^^^^^^^^^^^^^^
  File "C:\Users\ge84gac\.conda\envs\qbmqsp\Lib\site-packages\urllib3\util\retry.py", line 515, in increment
    raise MaxRetryError(_pool, url, reason) from reason  # type: ignore[arg-type]
    ^^^^^^^^^^^^^^^^^^^^^^^^^^^^^^^^^^^^^^^^^^^^^^^^^^^
urllib3.exceptions.MaxRetryError: HTTPSConnectionPool(host='api.wandb.ai', port=443): Max retries exceeded with url: /graphql (Caused by NameResolutionError("<urllib3.connection.HTTPSConnection object at 0x0000027533BCF710>: Failed to resolve 'api.wandb.ai' ([Errno 11001] getaddrinfo failed)"))

During handling of the above exception, another exception occurred:

Traceback (most recent call last):
  File "C:\Users\ge84gac\.conda\envs\qbmqsp\Lib\site-packages\wandb\sdk\lib\retry.py", line 131, in __call__
    result = self._call_fn(*args, **kwargs)
             ^^^^^^^^^^^^^^^^^^^^^^^^^^^^^^
  File "C:\Users\ge84gac\.conda\envs\qbmqsp\Lib\site-packages\wandb\sdk\internal\internal_api.py", line 345, in execute
    return self.client.execute(*args, **kwargs)  # type: ignore
           ^^^^^^^^^^^^^^^^^^^^^^^^^^^^^^^^^^^^
  File "C:\Users\ge84gac\.conda\envs\qbmqsp\Lib\site-packages\wandb\vendor\gql-0.2.0\wandb_gql\client.py", line 52, in execute
    result = self._get_result(document, *args, **kwargs)
             ^^^^^^^^^^^^^^^^^^^^^^^^^^^^^^^^^^^^^^^^^^^
  File "C:\Users\ge84gac\.conda\envs\qbmqsp\Lib\site-packages\wandb\vendor\gql-0.2.0\wandb_gql\client.py", line 60, in _get_result
    return self.transport.execute(document, *args, **kwargs)
           ^^^^^^^^^^^^^^^^^^^^^^^^^^^^^^^^^^^^^^^^^^^^^^^^^
  File "C:\Users\ge84gac\.conda\envs\qbmqsp\Lib\site-packages\wandb\sdk\lib\gql_request.py", line 58, in execute
    request = self.session.post(self.url, **post_args)
              ^^^^^^^^^^^^^^^^^^^^^^^^^^^^^^^^^^^^^^^^
  File "C:\Users\ge84gac\.conda\envs\qbmqsp\Lib\site-packages\requests\sessions.py", line 637, in post
    return self.request("POST", url, data=data, json=json, **kwargs)
           ^^^^^^^^^^^^^^^^^^^^^^^^^^^^^^^^^^^^^^^^^^^^^^^^^^^^^^^^^
  File "C:\Users\ge84gac\.conda\envs\qbmqsp\Lib\site-packages\requests\sessions.py", line 589, in request
    resp = self.send(prep, **send_kwargs)
           ^^^^^^^^^^^^^^^^^^^^^^^^^^^^^^
  File "C:\Users\ge84gac\.conda\envs\qbmqsp\Lib\site-packages\requests\sessions.py", line 703, in send
    r = adapter.send(request, **kwargs)
        ^^^^^^^^^^^^^^^^^^^^^^^^^^^^^^^
  File "C:\Users\ge84gac\.conda\envs\qbmqsp\Lib\site-packages\requests\adapters.py", line 622, in send
    raise ConnectionError(e, request=request)
requests.exceptions.ConnectionError: HTTPSConnectionPool(host='api.wandb.ai', port=443): Max retries exceeded with url: /graphql (Caused by NameResolutionError("<urllib3.connection.HTTPSConnection object at 0x0000027533BCF710>: Failed to resolve 'api.wandb.ai' ([Errno 11001] getaddrinfo failed)"))
2024-07-24 17:30:31,029 INFO    Thread-138 (_run_job):9552 [wandb_run.py:_finish():2109] finishing run shivang_arora/Gate-qbm-anomaly-detection-multiple/sbiizh6w
2024-07-24 17:30:31,031 INFO    Thread-138 (_run_job):9552 [jupyter.py:save_history():444] not saving jupyter history
2024-07-24 17:30:31,031 INFO    Thread-138 (_run_job):9552 [jupyter.py:save_ipynb():372] not saving jupyter notebook
2024-07-24 17:30:31,031 INFO    Thread-138 (_run_job):9552 [wandb_init.py:_jupyter_teardown():457] cleaning up jupyter logic
2024-07-24 17:30:31,031 INFO    Thread-138 (_run_job):9552 [wandb_run.py:_atexit_cleanup():2349] got exitcode: 0
2024-07-24 17:30:31,032 INFO    Thread-138 (_run_job):9552 [wandb_run.py:_restore():2332] restore
2024-07-24 17:30:31,032 INFO    Thread-138 (_run_job):9552 [wandb_run.py:_restore():2338] restore done
2024-07-24 17:30:37,292 INFO    Thread-138 (_run_job):9552 [wandb_run.py:_footer_history_summary_info():3991] rendering history
2024-07-24 17:30:37,293 INFO    Thread-138 (_run_job):9552 [wandb_run.py:_footer_history_summary_info():4023] rendering summary
2024-07-24 17:30:37,311 INFO    Thread-138 (_run_job):9552 [wandb_run.py:_footer_sync_info():3950] logging synced files
